17-09-2019 20:09:1563365348 root:ERROR:Exception occurred
Traceback (most recent call last):
  File "4mian.py", line 6, in <module>
    c = a / b
ZeroDivisionError: division by zero
17-09-2019 20:09:1563365348 root:ERROR:Exception occurred
Traceback (most recent call last):
  File "4mian.py", line 6, in <module>
    c = a / b
ZeroDivisionError: division by zero
17-09-2019 20:09:1563365348 root:DEBUG:Exception occurred
Traceback (most recent call last):
  File "4mian.py", line 6, in <module>
    c = a / b
ZeroDivisionError: division by zero
